Workbook

Sheet README
A1: UniConnect — Student Portal Consolidation — Project data workbook
A2: BISY2004 Assessment 2 | Group XX | Scenario C | Fictional organisation: Southern Coast University (SCU) — fictional | Status date: Fri 25 Sep 2026
A3: Everything comes from one data file (data/project.yaml), so the WBS IDs are the same in ProjectLibre, Trello, this workbook and the diagrams. Numbers you type in are inputs; everything else is a formula.
A5: Sheet | B5: Purpose
A6: =HYPERLINK("#'Resources'!A1","Resources") -> Resources | B6: Role rates (AUD/hour) and headcount — input to all labour costs
A7: =HYPERLINK("#'Assignments'!A1","Assignments") -> Assignments | B7: Task × role × units → hours × rate = labour cost (formulas)
A8: =HYPERLINK("#'Schedule_WBS'!A1","Schedule_WBS") -> Schedule_WBS | B8: WBS work packages with ProjectLibre IDs, baseline/forecast dates, float, cost, % complete, PV/EV/AC
A9: =HYPERLINK("#'Risk_Register'!A1","Risk_Register") -> Risk_Register | B9: 13 risks, 5×5 scoring (Score = L×I), rating bands, residual risk, EMV → contingency reserve
A10: =HYPERLINK("#'Risk_Heatmap_5x5'!A1","Risk_Heatmap_5x5") -> Risk_Heatmap_5x5 | B10: Inherent and residual heat maps (COUNTIFS) with risk IDs in each cell
A11: =HYPERLINK("#'Cost_Baseline'!A1","Cost_Baseline") -> Cost_Baseline | B11: Cost by WBS branch, BAC, contingency + management reserve, total budget, monthly time-phased PV
A12: =HYPERLINK("#'EVM_Status'!A1","EVM_Status") -> EVM_Status | B12: Weekly PV/EV/AC to the status date; SV, CV, SPI, CPI, EAC (3 methods), ETC, VAC, TCPI with RAG
A13: =HYPERLINK("#'Dashboard'!A1","Dashboard") -> Dashboard | B13: KPI tiles, S-curve, risks by rating, milestone status, quality status
A14: =HYPERLINK("#'Stakeholder_Register'!A1","Stakeholder_Register") -> Stakeholder_Register | B14: Power/interest scores, quadrant formula, reason, attitude current→desired, strategy
A15: =HYPERLINK("#'Comms_Plan'!A1","Comms_Plan") -> Comms_Plan | B15: Who gets what, how, how often, owner, feedback loop
A16: =HYPERLINK("#'RACI'!A1","RACI") -> RACI | B16: Deliverables × roles with an 'exactly one A' check per row
A17: =HYPERLINK("#'Quality_Metrics'!A1","Quality_Metrics") -> Quality_Metrics | B17: Metrics, targets, current values, RAG
A18: =HYPERLINK("#'Control_Chart'!A1","Control_Chart") -> Control_Chart | B18: Defects per week with mean, UCL = mean + 3σ, LCL = max(0, mean − 3σ)
A19: =HYPERLINK("#'Change_Log'!A1","Change_Log") -> Change_Log | B19: CR-01..03 with scope/schedule/cost/risk impact and CCB decision
A20: =HYPERLINK("#'Issue_Log'!A1","Issue_Log") -> Issue_Log | B20: ISS-01..05 linked to risks, WBS, owners and actions
A21: =HYPERLINK("#'Traceability'!A1","Traceability") -> Traceability | B21: WBS → ProjectLibre ID → Trello card → cost → risks → RACI accountable → quality metric
A22: =HYPERLINK("#'Closure'!A1","Closure") -> Closure | B22: Closure checklist, benefits realisation plan, lessons learned
A23: =HYPERLINK("#'Lookups'!A1","Lookups") -> Lookups | B23: Validation lists and the 5×5 scoring scales
A25: How to read the status words
A26: Green | B26: on target (SPI/CPI 0.95 or more)
A27: Amber | B27: keep an eye on it (0.90 to 0.95)
A28: Red | B28: needs action now (under 0.90)
A29: Note | B29: No colours are used, so every rating is written as a word in the cell.

Sheet Dashboard
A1: UniConnect — Project status dashboard (status date 25 Sep 2026)
A2: Every tile is a formula that pulls from EVM_Status, Risk_Register, Issue_Log, Change_Log and Quality_Metrics.
A4: SPI | E4: CPI | I4: % complete | M4: EAC
A5: =SPI -> 0.91363262 | E5: =CPI -> 0.95727787 | I5: =EVM_Status!L18 -> 0.24642849 | M5: =EAC -> 940353.93
A8: VAC | E8: Open High risks | I8: Open issues | M8: CRs approved
A9: =VAC -> -40173.926 | E9: =Risk_Register!T21 -> 7 | I9: =Issue_Log!B11 -> 3 | M9: =COUNTIF(Change_Log!K5:K7,"Approved")&" of "&COUNTA(Change_Log!A5:A7) -> 2 of 3
A12: Overall RAG | B12: =IF(OR(SPI<0.9,CPI<0.9),"RED",IF(OR(SPI<0.95,CPI<0.95),"AMBER","GREEN")) -> AMBER | D12: ="Forecast go-live "&TEXT(E21,"dd/mm/yyyy")&" vs hard deadline 05/02/2027 — buffer "&(NETWORKDAYS(E21,DATE(2027,2,5),Holidays)-1)&" working day(s) before CR-02 recovery" -> Forecast go-live 04/02/2027 vs hard deadline 05/02/2027 — buffer 1 working day(s) before CR-02 recovery
A14: Milestones | I14: Quality metrics
A15: ID | B15: Milestone | D15: Baseline | E15: Forecast | F15: Slip (d) | G15: Status | I15: ID | J15: Metric | M15: Current | O15: RAG
A16: M1 | B16: Charter approved | D16: 46220 | E16: 46220 | F16: =IF(E16<=D16,0,NETWORKDAYS(D16,E16,Holidays)-1) -> 0 | G16: Achieved | I16: =Quality_Metrics!A5 -> Q01 | J16: =Quality_Metrics!B5 -> Migration record accuracy | M16: =Quality_Metrics!G5 -> 95.3% (trial 1) | O16: =Quality_Metrics!H5 -> Red
A17: M2 | B17: Design sign-off | D17: 46269 | E17: 46269 | F17: =IF(E17<=D17,0,NETWORKDAYS(D17,E17,Holidays)-1) -> 0 | G17: Achieved | I17: =Quality_Metrics!A6 -> Q02 | J17: =Quality_Metrics!B6 -> Portal availability | M17: =Quality_Metrics!G6 -> 99.2% (test env.) | O17: =Quality_Metrics!H6 -> Amber
A18: M3 | B18: Build complete | D18: 46321 | E18: 46321 | F18: =IF(E18<=D18,0,NETWORKDAYS(D18,E18,Holidays)-1) -> 0 | G18: =IF(F18>0,"At risk","On track") -> On track | I18: =Quality_Metrics!A7 -> Q03 | J18: =Quality_Metrics!B7 -> Page load p95 at 5,000 concurrent users | M18: =Quality_Metrics!G7 -> Not yet tested | O18: =Quality_Metrics!H7 -> Grey
A19: M4 | B19: Trial migration passed | D19: 46328 | E19: 46342 | F19: =IF(E19<=D19,0,NETWORKDAYS(D19,E19,Holidays)-1) -> 10 | G19: =IF(F19>0,"At risk","On track") -> At risk | I19: =Quality_Metrics!A8 -> Q04 | J19: =Quality_Metrics!B8 -> WCAG 2.1 AA critical failures | M19: =Quality_Metrics!G8 -> 2 (Sprint 1 scan) | O19: =Quality_Metrics!H8 -> Amber
A20: M5 | B20: UAT sign-off | D20: 46370 | E20: 46393 | F20: =IF(E20<=D20,0,NETWORKDAYS(D20,E20,Holidays)-1) -> 10 | G20: =IF(F20>0,"At risk","On track") -> At risk | I20: =Quality_Metrics!A9 -> Q05 | J20: =Quality_Metrics!B9 -> UAT pass rate | M20: =Quality_Metrics!G9 -> Not started | O20: =Quality_Metrics!H9 -> Grey
A21: M6 | B21: Go-live | D21: 46407 | E21: 46422 | F21: =IF(E21<=D21,0,NETWORKDAYS(D21,E21,Holidays)-1) -> 10 | G21: =IF(F21>0,"At risk","On track") -> At risk | I21: =Quality_Metrics!A10 -> Q06 | J21: =Quality_Metrics!B10 -> Open Severity-1 defects at go-live | M21: =Quality_Metrics!G10 -> 1 open (ISS-02) | O21: =Quality_Metrics!H10 -> Amber
A22: M7 | B22: Project closed | D22: 46457 | E22: 46471 | F22: =IF(E22<=D22,0,NETWORKDAYS(D22,E22,Holidays)-1) -> 10 | G22: =IF(F22>0,"At risk","On track") -> At risk | I22: =Quality_Metrics!A11 -> Q07 | J22: =Quality_Metrics!B11 -> Portal-related helpdesk tickets | M22: =Quality_Metrics!G11 -> Baseline 4,200/month | O22: =Quality_Metrics!H11 -> Grey
A25: Risks by rating
A26: Rating | B26: Inherent | C26: Residual
A27: Extreme | B27: =COUNTIF(Risk_Register!$I$5:$I$17,A27) -> 0 | C27: =COUNTIF(Risk_Register!$Q$5:$Q$17,A27) -> 0
A28: High | B28: =COUNTIF(Risk_Register!$I$5:$I$17,A28) -> 7 | C28: =COUNTIF(Risk_Register!$Q$5:$Q$17,A28) -> 1
A29: Medium | B29: =COUNTIF(Risk_Register!$I$5:$I$17,A29) -> 6 | C29: =COUNTIF(Risk_Register!$Q$5:$Q$17,A29) -> 7
A30: Low | B30: =COUNTIF(Risk_Register!$I$5:$I$17,A30) -> 0 | C30: =COUNTIF(Risk_Register!$Q$5:$Q$17,A30) -> 5

Sheet Risk_Register
A1: Risk register (5×5)
A2: Score = L × I; bands Low 1–4, Medium 5–9, High 10–16, Extreme 20–25; EMV = probability × cost impact
A4: ID | B4: Type | C4: Category | D4: Description (cause → event → effect) | E4: WBS links | F4: L | G4: I | H4: Score | I4: Rating | J4: Owner | K4: Strategy | L4: Response | M4: Trigger | N4: Res. L | O4: Res. I | P4: Res. score | Q4: Res. rating | R4: Probability | S4: Cost impact | T4: EMV | U4: Status | V4: Heat key | W4: Res. key
A5: R01 | B5: threat | C5: Data | D5: Because legacy SIS/portal data has duplicate and inconsistent student records (cause), trial migration may fail reconciliation (event), delaying the critical migration path and go-live (effect). | E5: 4.1, 4.2, 4.3 | F5: 4 | G5: 4 | H5: =F5*G5 -> 16 | I5: =IF(H5>=20,"Extreme",IF(H5>=10,"High",IF(H5>=5,"Medium","Low"))) -> High | J5: Data Engineer | K5: Mitigate | L5: Early data profiling in 2.1; de-duplication rules in 4.1; reconciliation scripts; contingency: cleansing mini-sprint + contractor. | M5: > 1% duplicate/unmatched records in trial migration 1 | N5: 2 | O5: 3 | P5: =N5*O5 -> 6 | Q5: =IF(P5>=20,"Extreme",IF(P5>=10,"High",IF(P5>=5,"Medium","Low"))) -> Medium | R5: =VLOOKUP(F5,ProbTable,4,FALSE()) -> 0.65 | S5: 60000 | T5: =R5*S5 -> 39000 | U5: Materialised → ISS-01 | V5: =F5&"-"&G5 -> 4-4 | W5: =N5&"-"&O5 -> 2-3
A6: R02 | B6: threat | C6: Technical/Vendor | D6: Because the LMS vendor's SSO/API support is immature (cause), SSO or LMS integration may not work (event), delaying Sprint 1 and integration APIs (effect). | E6: 2.3, 3.1, 3.5 | F6: 3 | G6: 4 | H6: =F6*G6 -> 12 | I6: =IF(H6>=20,"Extreme",IF(H6>=10,"High",IF(H6>=5,"Medium","Low"))) -> High | J6: Solution Architect | K6: Mitigate | L6: SSO proof of concept in Sprint 1; vendor SLA with escalation; weekly vendor call (C07). | M6: SSO PoC fails token exchange by end of Sprint 1 | N6: 2 | O6: 3 | P6: =N6*O6 -> 6 | Q6: =IF(P6>=20,"Extreme",IF(P6>=10,"High",IF(P6>=5,"Medium","Low"))) -> Medium | R6: =VLOOKUP(F6,ProbTable,4,FALSE()) -> 0.4 | S6: 15000 | T6: =R6*S6 -> 6000 | U6: Open — partly occurred (ISS-02) | V6: =F6&"-"&G6 -> 3-4 | W6: =N6&"-"&O6 -> 2-3
A7: R03 | B7: threat | C7: Compliance/Privacy | D7: Because migration copies identifiable student data between environments (cause), personal information could be exposed (event), causing a notifiable data breach under APP 11 (effect). | E7: 2.4, 4.2, 4.3, 4.4 | F7: 2 | G7: 5 | H7: =F7*G7 -> 10 | I7: =IF(H7>=20,"Extreme",IF(H7>=10,"High",IF(H7>=5,"Medium","Low"))) -> High | J7: Privacy Officer | K7: Mitigate | L7: PIA; masked data in non-production; encrypted transfer; access logging; MFA for all users (CR-03). | M7: Any unmasked personal data found in a non-production environment | N7: 1 | O7: 5 | P7: =N7*O7 -> 5 | Q7: =IF(P7>=20,"Extreme",IF(P7>=10,"High",IF(P7>=5,"Medium","Low"))) -> Medium | R7: =VLOOKUP(F7,ProbTable,4,FALSE()) -> 0.15 | S7: 40000 | T7: =R7*S7 -> 6000 | U7: Open | V7: =F7&"-"&G7 -> 2-5 | W7: =N7&"-"&O7 -> 1-5
A8: R04 | B8: threat | C8: Schedule | D8: Because go-live is close to Semester 1 enrolment (cause), cutover could clash with the enrolment peak (event), disrupting enrolments (effect). | E8: 4.4, 6.3 | F8: 3 | G8: 4 | H8: =F8*G8 -> 12 | I8: =IF(H8>=20,"Extreme",IF(H8>=10,"High",IF(H8>=5,"Medium","Low"))) -> High | J8: Project Manager | K8: Avoid | L8: Fixed cutover window 14–20 Jan 2027, change freeze from 1 Feb; fallback: go-live in mid-semester break with legacy portals kept live. | M8: Forecast go-live later than 29 Jan 2027 | N8: 1 | O8: 4 | P8: =N8*O8 -> 4 | Q8: =IF(P8>=20,"Extreme",IF(P8>=10,"High",IF(P8>=5,"Medium","Low"))) -> Low | R8: =VLOOKUP(F8,ProbTable,4,FALSE()) -> 0.4 | S8: 15000 | T8: =R8*S8 -> 6000 | U8: Open — watch (forecast go-live 4 Feb vs 5 Feb deadline) | V8: =F8&"-"&G8 -> 3-4 | W8: =N8&"-"&O8 -> 1-4
A9: R05 | B9: threat | C9: Resource | D9: Because developers are in high demand (cause), a key developer may resign (event), slowing sprints (effect). | E9: 3.1, 3.2, 3.3, 3.4 | F9: 2 | G9: 3 | H9: =F9*G9 -> 6 | I9: =IF(H9>=20,"Extreme",IF(H9>=10,"High",IF(H9>=5,"Medium","Low"))) -> Medium | J9: Development Lead | K9: Mitigate | L9: Pair programming, documented code, retention bonus at go-live. | M9: Resignation notice from a developer | N9: 2 | O9: 2 | P9: =N9*O9 -> 4 | Q9: =IF(P9>=20,"Extreme",IF(P9>=10,"High",IF(P9>=5,"Medium","Low"))) -> Low | R9: =VLOOKUP(F9,ProbTable,4,FALSE()) -> 0.15 | S9: 15000 | T9: =R9*S9 -> 2250 | U9: Open | V9: =F9&"-"&G9 -> 2-3 | W9: =N9&"-"&O9 -> 2-2
A10: R06 | B10: threat | C10: Scope | D10: Because faculties want their own features (cause), unapproved scope may enter sprints (event), consuming float and budget (effect). | E10: 2.2, 3.2, 3.3, 3.4 | F10: 4 | G10: 3 | H10: =F10*G10 -> 12 | I10: =IF(H10>=20,"Extreme",IF(H10>=10,"High",IF(H10>=5,"Medium","Low"))) -> High | J10: Project Manager | K10: Mitigate | L10: MoSCoW backlog; all requests through CCB (C05); Phase 2 backlog. | M10: > 2 new feature requests in a sprint | N10: 2 | O10: 3 | P10: =N10*O10 -> 6 | Q10: =IF(P10>=20,"Extreme",IF(P10>=10,"High",IF(P10>=5,"Medium","Low"))) -> Medium | R10: =VLOOKUP(F10,ProbTable,4,FALSE()) -> 0.65 | S10: 10000 | T10: =R10*S10 -> 6500 | U10: Occurred → CR-01 deferred | V10: =F10&"-"&G10 -> 4-3 | W10: =N10&"-"&O10 -> 2-3
A11: R07 | B11: threat | C11: Technical/Performance | D11: Because 5,000+ students log in at once during enrolment (cause), the portal could slow or fail (event), stopping enrolments (effect). | E11: 5.4, 6.3 | F11: 3 | G11: 5 | H11: =F11*G11 -> 15 | I11: =IF(H11>=20,"Extreme",IF(H11>=10,"High",IF(H11>=5,"Medium","Low"))) -> High | J11: Solution Architect | K11: Mitigate | L11: Load test at 5,000 concurrent users; autoscaling; CDN caching. | M11: p95 page load > 2 s in load test | N11: 2 | O11: 4 | P11: =N11*O11 -> 8 | Q11: =IF(P11>=20,"Extreme",IF(P11>=10,"High",IF(P11>=5,"Medium","Low"))) -> Medium | R11: =VLOOKUP(F11,ProbTable,4,FALSE()) -> 0.4 | S11: 15000 | T11: =R11*S11 -> 6000 | U11: Open | V11: =F11&"-"&G11 -> 3-5 | W11: =N11&"-"&O11 -> 2-4
A12: R08 | B12: threat | C12: Compliance/Accessibility | D12: Because legacy templates are not accessible (cause), the portal may fail WCAG 2.1 AA (event), excluding students with disability (effect). | E12: 2.5, 5.3 | F12: 3 | G12: 3 | H12: =F12*G12 -> 9 | I12: =IF(H12>=20,"Extreme",IF(H12>=10,"High",IF(H12>=5,"Medium","Low"))) -> Medium | J12: UX Designer | K12: Mitigate | L12: Accessible design system; automated scans each sprint; audit 5.3. | M12: Any critical failure in a sprint accessibility scan | N12: 1 | O12: 3 | P12: =N12*O12 -> 3 | Q12: =IF(P12>=20,"Extreme",IF(P12>=10,"High",IF(P12>=5,"Medium","Low"))) -> Low | R12: =VLOOKUP(F12,ProbTable,4,FALSE()) -> 0.4 | S12: 10000 | T12: =R12*S12 -> 4000 | U12: Open — ISS-04 | V12: =F12&"-"&G12 -> 3-3 | W12: =N12&"-"&O12 -> 1-3
A13: R09 | B13: threat | C13: Organisational | D13: Because students are used to the old portals (cause), adoption may be low (event), reducing benefits (effect). | E13: 6.1, 6.2 | F13: 3 | G13: 3 | H13: =F13*G13 -> 9 | I13: =IF(H13>=20,"Extreme",IF(H13>=10,"High",IF(H13>=5,"Medium","Low"))) -> Medium | J13: Change & Training Lead | K13: Mitigate | L13: SRC co-design; pilot champions; go-live campaign (C04, C08). | M13: Pilot satisfaction < 70% | N13: 2 | O13: 2 | P13: =N13*O13 -> 4 | Q13: =IF(P13>=20,"Extreme",IF(P13>=10,"High",IF(P13>=5,"Medium","Low"))) -> Low | R13: =VLOOKUP(F13,ProbTable,4,FALSE()) -> 0.4 | S13: 8000 | T13: =R13*S13 -> 3200 | U13: Open | V13: =F13&"-"&G13 -> 3-3 | W13: =N13&"-"&O13 -> 2-2
A14: R10 | B14: threat | C14: Financial | D14: Because licences are priced in USD (cause), a weaker AUD could raise licence costs (event), exceeding the cost baseline (effect). | E14: 6.3 | F14: 3 | G14: 3 | H14: =F14*G14 -> 9 | I14: =IF(H14>=20,"Extreme",IF(H14>=10,"High",IF(H14>=5,"Medium","Low"))) -> Medium | J14: Finance Office | K14: Transfer | L14: Fixed-AUD pricing clause negotiated with the vendor. | M14: AUD/USD < 0.62 before contract signature | N14: 1 | O14: 3 | P14: =N14*O14 -> 3 | Q14: =IF(P14>=20,"Extreme",IF(P14>=10,"High",IF(P14>=5,"Medium","Low"))) -> Low | R14: =VLOOKUP(F14,ProbTable,4,FALSE()) -> 0.4 | S14: 10000 | T14: =R14*S14 -> 4000 | U14: Open — fixed-AUD clause in negotiation | V14: =F14&"-"&G14 -> 3-3 | W14: =N14&"-"&O14 -> 1-3
A15: R11 | B15: threat | C15: Operational | D15: Because all students switch at once (cause), the Service Desk may be overwhelmed (event), causing long waits and complaints (effect). | E15: 6.1, 6.4 | F15: 4 | G15: 3 | H15: =F15*G15 -> 12 | I15: =IF(H15>=20,"Extreme",IF(H15>=10,"High",IF(H15>=5,"Medium","Low"))) -> High | J15: Change & Training Lead | K15: Mitigate | L15: FAQs, chatbot, surge staff roster, daily hypercare stand-up (C09). | M15: > 300 portal tickets/day during hypercare | N15: 2 | O15: 3 | P15: =N15*O15 -> 6 | Q15: =IF(P15>=20,"Extreme",IF(P15>=10,"High",IF(P15>=5,"Medium","Low"))) -> Medium | R15: =VLOOKUP(F15,ProbTable,4,FALSE()) -> 0.65 | S15: 8000 | T15: =R15*S15 -> 5200 | U15: Open | V15: =F15&"-"&G15 -> 4-3 | W15: =N15&"-"&O15 -> 2-3
A16: R12 | B16: opportunity | C16: Opportunity | D16: Because SCU already runs an identity platform (cause), SSO could reuse it (event), avoiding a separate identity licence and speeding Sprint 1 (effect). | E16: 2.3, 3.1 | F16: 3 | G16: 3 | H16: =F16*G16 -> 9 | I16: =IF(H16>=20,"Extreme",IF(H16>=10,"High",IF(H16>=5,"Medium","Low"))) -> Medium | J16: Solution Architect | K16: Exploit | L16: Design SSO on the existing platform; cancel separate IdP quote. | M16: Architecture review confirms compatibility | N16: 5 | O16: 3 | P16: =N16*O16 -> 15 | Q16: =IF(P16>=20,"Extreme",IF(P16>=10,"High",IF(P16>=5,"Medium","Low"))) -> High | R16: =VLOOKUP(F16,ProbTable,4,FALSE()) -> 0.4 | S16: -30000 | T16: =R16*S16 -> -12000 | U16: Realised in 2.3 (saving not netted from reserve) | V16: =F16&"-"&G16 -> 3-3 | W16: =N16&"-"&O16 -> 5-3
A17: R13 | B17: threat | C17: Schedule | D17: Because of the university shutdown and staff leave over summer (cause), key people may be unavailable (event), slowing the faculty pilot (effect). | E17: 6.2 | F17: 4 | G17: 2 | H17: =F17*G17 -> 8 | I17: =IF(H17>=20,"Extreme",IF(H17>=10,"High",IF(H17>=5,"Medium","Low"))) -> Medium | J17: Project Manager | K17: Accept | L17: Accepted: shutdown modelled in the ProjectLibre calendar; leave plan agreed by Oct. | M17: Leave requests overlapping 6.2 | N17: 4 | O17: 2 | P17: =N17*O17 -> 8 | Q17: =IF(P17>=20,"Extreme",IF(P17>=10,"High",IF(P17>=5,"Medium","Low"))) -> Medium | R17: =VLOOKUP(F17,ProbTable,4,FALSE()) -> 0.65 | S17: 4000 | T17: =R17*S17 -> 2600 | U17: Accepted | V17: =F17&"-"&G17 -> 4-2 | W17: =N17&"-"&O17 -> 4-2
M19: Contingency reserve (threat EMV) | T19: =SUMIF(B5:B17,"threat",T5:T17) -> 90750
M20: Opportunity EMV (not netted) | T20: =SUMIF(B5:B17,"opportunity",T5:T17) -> -12000
M21: High/Extreme risks open | T21: =COUNTIF(I5:I17,"High")+COUNTIF(I5:I17,"Extreme") -> 7

Sheet Risk_Heatmap_5x5
A1: 5×5 risk heat map (inherent and residual)
A2: Each cell counts the risks at that likelihood and impact (COUNTIFS), then shows the band and the risk IDs. Bands: 1–4 Low, 5–9 Medium, 10–16 High, 20–25 Extreme.
A4: Inherent risk (before response) | G4: Residual risk (after response)
A5: Likelihood ↓ / Impact → | B5: 1 Insignificant | C5: 2 Minor | D5: 3 Moderate | E5: 4 Major | F5: 5 Severe | G5: Likelihood ↓ / Impact → | H5: 1 Insignificant | I5: 2 Minor | J5: 3 Moderate | K5: 4 Major | L5: 5 Severe
A6: 5 Almost certain | B6: =IF(COUNTIFS(Risk_Register!$F$5:$F$17,5,Risk_Register!$G$5:$G$17,1)=0,"",COUNTIFS(Risk_Register!$F$5:$F$17,5,Risk_Register!$G$5:$G$17,1)&" · Medium"&CHAR(10)&TRIM(IF(Risk_Register!$V$5="5-1",Risk_Register!$A$5&" ","")&IF(Risk_Register!$V$6="5-1",Risk_Register!$A$6&" ","")&IF(Risk_Register!$V$7="5-1",Risk_Register!$A$7&" ","")&IF(Risk_Register!$V$8="5-1",Risk_Register!$A$8&" ","")&IF(Risk_Register!$V$9="5-1",Risk_Register!$A$9&" ","")&IF(Risk_Register!$V$10="5-1",Risk_Register!$A$10&" ","")&IF(Risk_Register!$V$11="5-1",Risk_Register!$A$11&" ","")&IF(Risk_Register!$V$12="5-1",Risk_Register!$A$12&" ","")&IF(Risk_Register!$V$13="5-1",Risk_Register!$A$13&" ","")&IF(Risk_Register!$V$14="5-1",Risk_Register!$A$14&" ","")&IF(Risk_Register!$V$15="5-1",Risk_Register!$A$15&" ","")&IF(Risk_Register!$V$16="5-1",Risk_Register!$A$16&" ","")&IF(Risk_Register!$V$17="5-1",Risk_Register!$A$17&" ",""))) | C6: =IF(COUNTIFS(Risk_Register!$F$5:$F$17,5,Risk_Register!$G$5:$G$17,2)=0,"",COUNTIFS(Risk_Register!$F$5:$F$17,5,Risk_Register!$G$5:$G$17,2)&" · High"&CHAR(10)&TRIM(IF(Risk_Register!$V$5="5-2",Risk_Register!$A$5&" ","")&IF(Risk_Register!$V$6="5-2",Risk_Register!$A$6&" ","")&IF(Risk_Register!$V$7="5-2",Risk_Register!$A$7&" ","")&IF(Risk_Register!$V$8="5-2",Risk_Register!$A$8&" ","")&IF(Risk_Register!$V$9="5-2",Risk_Register!$A$9&" ","")&IF(Risk_Register!$V$10="5-2",Risk_Register!$A$10&" ","")&IF(Risk_Register!$V$11="5-2",Risk_Register!$A$11&" ","")&IF(Risk_Register!$V$12="5-2",Risk_Register!$A$12&" ","")&IF(Risk_Register!$V$13="5-2",Risk_Register!$A$13&" ","")&IF(Risk_Register!$V$14="5-2",Risk_Register!$A$14&" ","")&IF(Risk_Register!$V$15="5-2",Risk_Register!$A$15&" ","")&IF(Risk_Register!$V$16="5-2",Risk_Register!$A$16&" ","")&IF(Risk_Register!$V$17="5-2",Risk_Register!$A$17&" ",""))) | D6: =IF(COUNTIFS(Risk_Register!$F$5:$F$17,5,Risk_Register!$G$5:$G$17,3)=0,"",COUNTIFS(Risk_Register!$F$5:$F$17,5,Risk_Register!$G$5:$G$17,3)&" · High"&CHAR(10)&TRIM(IF(Risk_Register!$V$5="5-3",Risk_Register!$A$5&" ","")&IF(Risk_Register!$V$6="5-3",Risk_Register!$A$6&" ","")&IF(Risk_Register!$V$7="5-3",Risk_Register!$A$7&" ","")&IF(Risk_Register!$V$8="5-3",Risk_Register!$A$8&" ","")&IF(Risk_Register!$V$9="5-3",Risk_Register!$A$9&" ","")&IF(Risk_Register!$V$10="5-3",Risk_Register!$A$10&" ","")&IF(Risk_Register!$V$11="5-3",Risk_Register!$A$11&" ","")&IF(Risk_Register!$V$12="5-3",Risk_Register!$A$12&" ","")&IF(Risk_Register!$V$13="5-3",Risk_Register!$A$13&" ","")&IF(Risk_Register!$V$14="5-3",Risk_Register!$A$14&" ","")&IF(Risk_Register!$V$15="5-3",Risk_Register!$A$15&" ","")&IF(Risk_Register!$V$16="5-3",Risk_Register!$A$16&" ","")&IF(Risk_Register!$V$17="5-3",Risk_Register!$A$17&" ",""))) | E6: =IF(COUNTIFS(Risk_Register!$F$5:$F$17,5,Risk_Register!$G$5:$G$17,4)=0,"",COUNTIFS(Risk_Register!$F$5:$F$17,5,Risk_Register!$G$5:$G$17,4)&" · Extreme"&CHAR(10)&TRIM(IF(Risk_Register!$V$5="5-4",Risk_Register!$A$5&" ","")&IF(Risk_Register!$V$6="5-4",Risk_Register!$A$6&" ","")&IF(Risk_Register!$V$7="5-4",Risk_Register!$A$7&" ","")&IF(Risk_Register!$V$8="5-4",Risk_Register!$A$8&" ","")&IF(Risk_Register!$V$9="5-4",Risk_Register!$A$9&" ","")&IF(Risk_Register!$V$10="5-4",Risk_Register!$A$10&" ","")&IF(Risk_Register!$V$11="5-4",Risk_Register!$A$11&" ","")&IF(Risk_Register!$V$12="5-4",Risk_Register!$A$12&" ","")&IF(Risk_Register!$V$13="5-4",Risk_Register!$A$13&" ","")&IF(Risk_Register!$V$14="5-4",Risk_Register!$A$14&" ","")&IF(Risk_Register!$V$15="5-4",Risk_Register!$A$15&" ","")&IF(Risk_Register!$V$16="5-4",Risk_Register!$A$16&" ","")&IF(Risk_Register!$V$17="5-4",Risk_Register!$A$17&" ",""))) | F6: =IF(COUNTIFS(Risk_Register!$F$5:$F$17,5,Risk_Register!$G$5:$G$17,5)=0,"",COUNTIFS(Risk_Register!$F$5:$F$17,5,Risk_Register!$G$5:$G$17,5)&" · Extreme"&CHAR(10)&TRIM(IF(Risk_Register!$V$5="5-5",Risk_Register!$A$5&" ","")&IF(Risk_Register!$V$6="5-5",Risk_Register!$A$6&" ","")&IF(Risk_Register!$V$7="5-5",Risk_Register!$A$7&" ","")&IF(Risk_Register!$V$8="5-5",Risk_Register!$A$8&" ","")&IF(Risk_Register!$V$9="5-5",Risk_Register!$A$9&" ","")&IF(Risk_Register!$V$10="5-5",Risk_Register!$A$10&" ","")&IF(Risk_Register!$V$11="5-5",Risk_Register!$A$11&" ","")&IF(Risk_Register!$V$12="5-5",Risk_Register!$A$12&" ","")&IF(Risk_Register!$V$13="5-5",Risk_Register!$A$13&" ","")&IF(Risk_Register!$V$14="5-5",Risk_Register!$A$14&" ","")&IF(Risk_Register!$V$15="5-5",Risk_Register!$A$15&" ","")&IF(Risk_Register!$V$16="5-5",Risk_Register!$A$16&" ","")&IF(Risk_Register!$V$17="5-5",Risk_Register!$A$17&" ",""))) | G6: 5 Almost certain | H6: =IF(COUNTIFS(Risk_Register!$N$5:$N$17,5,Risk_Register!$O$5:$O$17,1)=0,"",COUNTIFS(Risk_Register!$N$5:$N$17,5,Risk_Register!$O$5:$O$17,1)&" · Medium"&CHAR(10)&TRIM(IF(Risk_Register!$W$5="5-1",Risk_Register!$A$5&" ","")&IF(Risk_Register!$W$6="5-1",Risk_Register!$A$6&" ","")&IF(Risk_Register!$W$7="5-1",Risk_Register!$A$7&" ","")&IF(Risk_Register!$W$8="5-1",Risk_Register!$A$8&" ","")&IF(Risk_Register!$W$9="5-1",Risk_Register!$A$9&" ","")&IF(Risk_Register!$W$10="5-1",Risk_Register!$A$10&" ","")&IF(Risk_Register!$W$11="5-1",Risk_Register!$A$11&" ","")&IF(Risk_Register!$W$12="5-1",Risk_Register!$A$12&" ","")&IF(Risk_Register!$W$13="5-1",Risk_Register!$A$13&" ","")&IF(Risk_Register!$W$14="5-1",Risk_Register!$A$14&" ","")&IF(Risk_Register!$W$15="5-1",Risk_Register!$A$15&" ","")&IF(Risk_Register!$W$16="5-1",Risk_Register!$A$16&" ","")&IF(Risk_Register!$W$17="5-1",Risk_Register!$A$17&" ",""))) | I6: =IF(COUNTIFS(Risk_Register!$N$5:$N$17,5,Risk_Register!$O$5:$O$17,2)=0,"",COUNTIFS(Risk_Register!$N$5:$N$17,5,Risk_Register!$O$5:$O$17,2)&" · High"&CHAR(10)&TRIM(IF(Risk_Register!$W$5="5-2",Risk_Register!$A$5&" ","")&IF(Risk_Register!$W$6="5-2",Risk_Register!$A$6&" ","")&IF(Risk_Register!$W$7="5-2",Risk_Register!$A$7&" ","")&IF(Risk_Register!$W$8="5-2",Risk_Register!$A$8&" ","")&IF(Risk_Register!$W$9="5-2",Risk_Register!$A$9&" ","")&IF(Risk_Register!$W$10="5-2",Risk_Register!$A$10&" ","")&IF(Risk_Register!$W$11="5-2",Risk_Register!$A$11&" ","")&IF(Risk_Register!$W$12="5-2",Risk_Register!$A$12&" ","")&IF(Risk_Register!$W$13="5-2",Risk_Register!$A$13&" ","")&IF(Risk_Register!$W$14="5-2",Risk_Register!$A$14&" ","")&IF(Risk_Register!$W$15="5-2",Risk_Register!$A$15&" ","")&IF(Risk_Register!$W$16="5-2",Risk_Register!$A$16&" ","")&IF(Risk_Register!$W$17="5-2",Risk_Register!$A$17&" ",""))) | J6: =IF(COUNTIFS(Risk_Register!$N$5:$N$17,5,Risk_Register!$O$5:$O$17,3)=0,"",COUNTIFS(Risk_Register!$N$5:$N$17,5,Risk_Register!$O$5:$O$17,3)&" · High"&CHAR(10)&TRIM(IF(Risk_Register!$W$5="5-3",Risk_Register!$A$5&" ","")&IF(Risk_Register!$W$6="5-3",Risk_Register!$A$6&" ","")&IF(Risk_Register!$W$7="5-3",Risk_Register!$A$7&" ","")&IF(Risk_Register!$W$8="5-3",Risk_Register!$A$8&" ","")&IF(Risk_Register!$W$9="5-3",Risk_Register!$A$9&" ","")&IF(Risk_Register!$W$10="5-3",Risk_Register!$A$10&" ","")&IF(Risk_Register!$W$11="5-3",Risk_Register!$A$11&" ","")&IF(Risk_Register!$W$12="5-3",Risk_Register!$A$12&" ","")&IF(Risk_Register!$W$13="5-3",Risk_Register!$A$13&" ","")&IF(Risk_Register!$W$14="5-3",Risk_Register!$A$14&" ","")&IF(Risk_Register!$W$15="5-3",Risk_Register!$A$15&" ","")&IF(Risk_Register!$W$16="5-3",Risk_Register!$A$16&" ","")&IF(Risk_Register!$W$17="5-3",Risk_Register!$A$17&" ",""))) -> 1 · High R12 | K6: =IF(COUNTIFS(Risk_Register!$N$5:$N$17,5,Risk_Register!$O$5:$O$17,4)=0,"",COUNTIFS(Risk_Register!$N$5:$N$17,5,Risk_Register!$O$5:$O$17,4)&" · Extreme"&CHAR(10)&TRIM(IF(Risk_Register!$W$5="5-4",Risk_Register!$A$5&" ","")&IF(Risk_Register!$W$6="5-4",Risk_Register!$A$6&" ","")&IF(Risk_Register!$W$7="5-4",Risk_Register!$A$7&" ","")&IF(Risk_Register!$W$8="5-4",Risk_Register!$A$8&" ","")&IF(Risk_Register!$W$9="5-4",Risk_Register!$A$9&" ","")&IF(Risk_Register!$W$10="5-4",Risk_Register!$A$10&" ","")&IF(Risk_Register!$W$11="5-4",Risk_Register!$A$11&" ","")&IF(Risk_Register!$W$12="5-4",Risk_Register!$A$12&" ","")&IF(Risk_Register!$W$13="5-4",Risk_Register!$A$13&" ","")&IF(Risk_Register!$W$14="5-4",Risk_Register!$A$14&" ","")&IF(Risk_Register!$W$15="5-4",Risk_Register!$A$15&" ","")&IF(Risk_Register!$W$16="5-4",Risk_Register!$A$16&" ","")&IF(Risk_Register!$W$17="5-4",Risk_Register!$A$17&" ",""))) | L6: =IF(COUNTIFS(Risk_Register!$N$5:$N$17,5,Risk_Register!$O$5:$O$17,5)=0,"",COUNTIFS(Risk_Register!$N$5:$N$17,5,Risk_Register!$O$5:$O$17,5)&" · Extreme"&CHAR(10)&TRIM(IF(Risk_Register!$W$5="5-5",Risk_Register!$A$5&" ","")&IF(Risk_Register!$W$6="5-5",Risk_Register!$A$6&" ","")&IF(Risk_Register!$W$7="5-5",Risk_Register!$A$7&" ","")&IF(Risk_Register!$W$8="5-5",Risk_Register!$A$8&" ","")&IF(Risk_Register!$W$9="5-5",Risk_Register!$A$9&" ","")&IF(Risk_Register!$W$10="5-5",Risk_Register!$A$10&" ","")&IF(Risk_Register!$W$11="5-5",Risk_Register!$A$11&" ","")&IF(Risk_Register!$W$12="5-5",Risk_Register!$A$12&" ","")&IF(Risk_Register!$W$13="5-5",Risk_Register!$A$13&" ","")&IF(Risk_Register!$W$14="5-5",Risk_Register!$A$14&" ","")&IF(Risk_Register!$W$15="5-5",Risk_Register!$A$15&" ","")&IF(Risk_Register!$W$16="5-5",Risk_Register!$A$16&" ","")&IF(Risk_Register!$W$17="5-5",Risk_Register!$A$17&" ","")))
A7: 4 Likely | B7: =IF(COUNTIFS(Risk_Register!$F$5:$F$17,4,Risk_Register!$G$5:$G$17,1)=0,"",COUNTIFS(Risk_Register!$F$5:$F$17,4,Risk_Register!$G$5:$G$17,1)&" · Low"&CHAR(10)&TRIM(IF(Risk_Register!$V$5="4-1",Risk_Register!$A$5&" ","")&IF(Risk_Register!$V$6="4-1",Risk_Register!$A$6&" ","")&IF(Risk_Register!$V$7="4-1",Risk_Register!$A$7&" ","")&IF(Risk_Register!$V$8="4-1",Risk_Register!$A$8&" ","")&IF(Risk_Register!$V$9="4-1",Risk_Register!$A$9&" ","")&IF(Risk_Register!$V$10="4-1",Risk_Register!$A$10&" ","")&IF(Risk_Register!$V$11="4-1",Risk_Register!$A$11&" ","")&IF(Risk_Register!$V$12="4-1",Risk_Register!$A$12&" ","")&IF(Risk_Register!$V$13="4-1",Risk_Register!$A$13&" ","")&IF(Risk_Register!$V$14="4-1",Risk_Register!$A$14&" ","")&IF(Risk_Register!$V$15="4-1",Risk_Register!$A$15&" ","")&IF(Risk_Register!$V$16="4-1",Risk_Register!$A$16&" ","")&IF(Risk_Register!$V$17="4-1",Risk_Register!$A$17&" ",""))) | C7: =IF(COUNTIFS(Risk_Register!$F$5:$F$17,4,Risk_Register!$G$5:$G$17,2)=0,"",COUNTIFS(Risk_Register!$F$5:$F$17,4,Risk_Register!$G$5:$G$17,2)&" · Medium"&CHAR(10)&TRIM(IF(Risk_Register!$V$5="4-2",Risk_Register!$A$5&" ","")&IF(Risk_Register!$V$6="4-2",Risk_Register!$A$6&" ","")&IF(Risk_Register!$V$7="4-2",Risk_Register!$A$7&" ","")&IF(Risk_Register!$V$8="4-2",Risk_Register!$A$8&" ","")&IF(Risk_Register!$V$9="4-2",Risk_Register!$A$9&" ","")&IF(Risk_Register!$V$10="4-2",Risk_Register!$A$10&" ","")&IF(Risk_Register!$V$11="4-2",Risk_Register!$A$11&" ","")&IF(Risk_Register!$V$12="4-2",Risk_Register!$A$12&" ","")&IF(Risk_Register!$V$13="4-2",Risk_Register!$A$13&" ","")&IF(Risk_Register!$V$14="4-2",Risk_Register!$A$14&" ","")&IF(Risk_Register!$V$15="4-2",Risk_Register!$A$15&" ","")&IF(Risk_Register!$V$16="4-2",Risk_Register!$A$16&" ","")&IF(Risk_Register!$V$17="4-2",Risk_Register!$A$17&" ",""))) -> 1 · Medium R13 | D7: =IF(COUNTIFS(Risk_Register!$F$5:$F$17,4,Risk_Register!$G$5:$G$17,3)=0,"",COUNTIFS(Risk_Register!$F$5:$F$17,4,Risk_Register!$G$5:$G$17,3)&" · High"&CHAR(10)&TRIM(IF(Risk_Register!$V$5="4-3",Risk_Register!$A$5&" ","")&IF(Risk_Register!$V$6="4-3",Risk_Register!$A$6&" ","")&IF(Risk_Register!$V$7="4-3",Risk_Register!$A$7&" ","")&IF(Risk_Register!$V$8="4-3",Risk_Register!$A$8&" ","")&IF(Risk_Register!$V$9="4-3",Risk_Register!$A$9&" ","")&IF(Risk_Register!$V$10="4-3",Risk_Register!$A$10&" ","")&IF(Risk_Register!$V$11="4-3",Risk_Register!$A$11&" ","")&IF(Risk_Register!$V$12="4-3",Risk_Register!$A$12&" ","")&IF(Risk_Register!$V$13="4-3",Risk_Register!$A$13&" ","")&IF(Risk_Register!$V$14="4-3",Risk_Register!$A$14&" ","")&IF(Risk_Register!$V$15="4-3",Risk_Register!$A$15&" ","")&IF(Risk_Register!$V$16="4-3",Risk_Register!$A$16&" ","")&IF(Risk_Register!$V$17="4-3",Risk_Register!$A$17&" ",""))) -> 2 · High R06 R11 | E7: =IF(COUNTIFS(Risk_Register!$F$5:$F$17,4,Risk_Register!$G$5:$G$17,4)=0,"",COUNTIFS(Risk_Register!$F$5:$F$17,4,Risk_Register!$G$5:$G$17,4)&" · High"&CHAR(10)&TRIM(IF(Risk_Register!$V$5="4-4",Risk_Register!$A$5&" ","")&IF(Risk_Register!$V$6="4-4",Risk_Register!$A$6&" ","")&IF(Risk_Register!$V$7="4-4",Risk_Register!$A$7&" ","")&IF(Risk_Register!$V$8="4-4",Risk_Register!$A$8&" ","")&IF(Risk_Register!$V$9="4-4",Risk_Register!$A$9&" ","")&IF(Risk_Register!$V$10="4-4",Risk_Register!$A$10&" ","")&IF(Risk_Register!$V$11="4-4",Risk_Register!$A$11&" ","")&IF(Risk_Register!$V$12="4-4",Risk_Register!$A$12&" ","")&IF(Risk_Register!$V$13="4-4",Risk_Register!$A$13&" ","")&IF(Risk_Register!$V$14="4-4",Risk_Register!$A$14&" ","")&IF(Risk_Register!$V$15="4-4",Risk_Register!$A$15&" ","")&IF(Risk_Register!$V$16="4-4",Risk_Register!$A$16&" ","")&IF(Risk_Register!$V$17="4-4",Risk_Register!$A$17&" ",""))) -> 1 · High R01 | F7: =IF(COUNTIFS(Risk_Register!$F$5:$F$17,4,Risk_Register!$G$5:$G$17,5)=0,"",COUNTIFS(Risk_Register!$F$5:$F$17,4,Risk_Register!$G$5:$G$17,5)&" · Extreme"&CHAR(10)&TRIM(IF(Risk_Register!$V$5="4-5",Risk_Register!$A$5&" ","")&IF(Risk_Register!$V$6="4-5",Risk_Register!$A$6&" ","")&IF(Risk_Register!$V$7="4-5",Risk_Register!$A$7&" ","")&IF(Risk_Register!$V$8="4-5",Risk_Register!$A$8&" ","")&IF(Risk_Register!$V$9="4-5",Risk_Register!$A$9&" ","")&IF(Risk_Register!$V$10="4-5",Risk_Register!$A$10&" ","")&IF(Risk_Register!$V$11="4-5",Risk_Register!$A$11&" ","")&IF(Risk_Register!$V$12="4-5",Risk_Register!$A$12&" ","")&IF(Risk_Register!$V$13="4-5",Risk_Register!$A$13&" ","")&IF(Risk_Register!$V$14="4-5",Risk_Register!$A$14&" ","")&IF(Risk_Register!$V$15="4-5",Risk_Register!$A$15&" ","")&IF(Risk_Register!$V$16="4-5",Risk_Register!$A$16&" ","")&IF(Risk_Register!$V$17="4-5",Risk_Register!$A$17&" ",""))) | G7: 4 Likely | H7: =IF(COUNTIFS(Risk_Register!$N$5:$N$17,4,Risk_Register!$O$5:$O$17,1)=0,"",COUNTIFS(Risk_Register!$N$5:$N$17,4,Risk_Register!$O$5:$O$17,1)&" · Low"&CHAR(10)&TRIM(IF(Risk_Register!$W$5="4-1",Risk_Register!$A$5&" ","")&IF(Risk_Register!$W$6="4-1",Risk_Register!$A$6&" ","")&IF(Risk_Register!$W$7="4-1",Risk_Register!$A$7&" ","")&IF(Risk_Register!$W$8="4-1",Risk_Register!$A$8&" ","")&IF(Risk_Register!$W$9="4-1",Risk_Register!$A$9&" ","")&IF(Risk_Register!$W$10="4-1",Risk_Register!$A$10&" ","")&IF(Risk_Register!$W$11="4-1",Risk_Register!$A$11&" ","")&IF(Risk_Register!$W$12="4-1",Risk_Register!$A$12&" ","")&IF(Risk_Register!$W$13="4-1",Risk_Register!$A$13&" ","")&IF(Risk_Register!$W$14="4-1",Risk_Register!$A$14&" ","")&IF(Risk_Register!$W$15="4-1",Risk_Register!$A$15&" ","")&IF(Risk_Register!$W$16="4-1",Risk_Register!$A$16&" ","")&IF(Risk_Register!$W$17="4-1",Risk_Register!$A$17&" ",""))) | I7: =IF(COUNTIFS(Risk_Register!$N$5:$N$17,4,Risk_Register!$O$5:$O$17,2)=0,"",COUNTIFS(Risk_Register!$N$5:$N$17,4,Risk_Register!$O$5:$O$17,2)&" · Medium"&CHAR(10)&TRIM(IF(Risk_Register!$W$5="4-2",Risk_Register!$A$5&" ","")&IF(Risk_Register!$W$6="4-2",Risk_Register!$A$6&" ","")&IF(Risk_Register!$W$7="4-2",Risk_Register!$A$7&" ","")&IF(Risk_Register!$W$8="4-2",Risk_Register!$A$8&" ","")&IF(Risk_Register!$W$9="4-2",Risk_Register!$A$9&" ","")&IF(Risk_Register!$W$10="4-2",Risk_Register!$A$10&" ","")&IF(Risk_Register!$W$11="4-2",Risk_Register!$A$11&" ","")&IF(Risk_Register!$W$12="4-2",Risk_Register!$A$12&" ","")&IF(Risk_Register!$W$13="4-2",Risk_Register!$A$13&" ","")&IF(Risk_Register!$W$14="4-2",Risk_Register!$A$14&" ","")&IF(Risk_Register!$W$15="4-2",Risk_Register!$A$15&" ","")&IF(Risk_Register!$W$16="4-2",Risk_Register!$A$16&" ","")&IF(Risk_Register!$W$17="4-2",Risk_Register!$A$17&" ",""))) -> 1 · Medium R13 | J7: =IF(COUNTIFS(Risk_Register!$N$5:$N$17,4,Risk_Register!$O$5:$O$17,3)=0,"",COUNTIFS(Risk_Register!$N$5:$N$17,4,Risk_Register!$O$5:$O$17,3)&" · High"&CHAR(10)&TRIM(IF(Risk_Register!$W$5="4-3",Risk_Register!$A$5&" ","")&IF(Risk_Register!$W$6="4-3",Risk_Register!$A$6&" ","")&IF(Risk_Register!$W$7="4-3",Risk_Register!$A$7&" ","")&IF(Risk_Register!$W$8="4-3",Risk_Register!$A$8&" ","")&IF(Risk_Register!$W$9="4-3",Risk_Register!$A$9&" ","")&IF(Risk_Register!$W$10="4-3",Risk_Register!$A$10&" ","")&IF(Risk_Register!$W$11="4-3",Risk_Register!$A$11&" ","")&IF(Risk_Register!$W$12="4-3",Risk_Register!$A$12&" ","")&IF(Risk_Register!$W$13="4-3",Risk_Register!$A$13&" ","")&IF(Risk_Register!$W$14="4-3",Risk_Register!$A$14&" ","")&IF(Risk_Register!$W$15="4-3",Risk_Register!$A$15&" ","")&IF(Risk_Register!$W$16="4-3",Risk_Register!$A$16&" ","")&IF(Risk_Register!$W$17="4-3",Risk_Register!$A$17&" ",""))) | K7: =IF(COUNTIFS(Risk_Register!$N$5:$N$17,4,Risk_Register!$O$5:$O$17,4)=0,"",COUNTIFS(Risk_Register!$N$5:$N$17,4,Risk_Register!$O$5:$O$17,4)&" · High"&CHAR(10)&TRIM(IF(Risk_Register!$W$5="4-4",Risk_Register!$A$5&" ","")&IF(Risk_Register!$W$6="4-4",Risk_Register!$A$6&" ","")&IF(Risk_Register!$W$7="4-4",Risk_Register!$A$7&" ","")&IF(Risk_Register!$W$8="4-4",Risk_Register!$A$8&" ","")&IF(Risk_Register!$W$9="4-4",Risk_Register!$A$9&" ","")&IF(Risk_Register!$W$10="4-4",Risk_Register!$A$10&" ","")&IF(Risk_Register!$W$11="4-4",Risk_Register!$A$11&" ","")&IF(Risk_Register!$W$12="4-4",Risk_Register!$A$12&" ","")&IF(Risk_Register!$W$13="4-4",Risk_Register!$A$13&" ","")&IF(Risk_Register!$W$14="4-4",Risk_Register!$A$14&" ","")&IF(Risk_Register!$W$15="4-4",Risk_Register!$A$15&" ","")&IF(Risk_Register!$W$16="4-4",Risk_Register!$A$16&" ","")&IF(Risk_Register!$W$17="4-4",Risk_Register!$A$17&" ",""))) | L7: =IF(COUNTIFS(Risk_Register!$N$5:$N$17,4,Risk_Register!$O$5:$O$17,5)=0,"",COUNTIFS(Risk_Register!$N$5:$N$17,4,Risk_Register!$O$5:$O$17,5)&" · Extreme"&CHAR(10)&TRIM(IF(Risk_Register!$W$5="4-5",Risk_Register!$A$5&" ","")&IF(Risk_Register!$W$6="4-5",Risk_Register!$A$6&" ","")&IF(Risk_Register!$W$7="4-5",Risk_Register!$A$7&" ","")&IF(Risk_Register!$W$8="4-5",Risk_Register!$A$8&" ","")&IF(Risk_Register!$W$9="4-5",Risk_Register!$A$9&" ","")&IF(Risk_Register!$W$10="4-5",Risk_Register!$A$10&" ","")&IF(Risk_Register!$W$11="4-5",Risk_Register!$A$11&" ","")&IF(Risk_Register!$W$12="4-5",Risk_Register!$A$12&" ","")&IF(Risk_Register!$W$13="4-5",Risk_Register!$A$13&" ","")&IF(Risk_Register!$W$14="4-5",Risk_Register!$A$14&" ","")&IF(Risk_Register!$W$15="4-5",Risk_Register!$A$15&" ","")&IF(Risk_Register!$W$16="4-5",Risk_Register!$A$16&" ","")&IF(Risk_Register!$W$17="4-5",Risk_Register!$A$17&" ","")))
A8: 3 Possible | B8: =IF(COUNTIFS(Risk_Register!$F$5:$F$17,3,Risk_Register!$G$5:$G$17,1)=0,"",COUNTIFS(Risk_Register!$F$5:$F$17,3,Risk_Register!$G$5:$G$17,1)&" · Low"&CHAR(10)&TRIM(IF(Risk_Register!$V$5="3-1",Risk_Register!$A$5&" ","")&IF(Risk_Register!$V$6="3-1",Risk_Register!$A$6&" ","")&IF(Risk_Register!$V$7="3-1",Risk_Register!$A$7&" ","")&IF(Risk_Register!$V$8="3-1",Risk_Register!$A$8&" ","")&IF(Risk_Register!$V$9="3-1",Risk_Register!$A$9&" ","")&IF(Risk_Register!$V$10="3-1",Risk_Register!$A$10&" ","")&IF(Risk_Register!$V$11="3-1",Risk_Register!$A$11&" ","")&IF(Risk_Register!$V$12="3-1",Risk_Register!$A$12&" ","")&IF(Risk_Register!$V$13="3-1",Risk_Register!$A$13&" ","")&IF(Risk_Register!$V$14="3-1",Risk_Register!$A$14&" ","")&IF(Risk_Register!$V$15="3-1",Risk_Register!$A$15&" ","")&IF(Risk_Register!$V$16="3-1",Risk_Register!$A$16&" ","")&IF(Risk_Register!$V$17="3-1",Risk_Register!$A$17&" ",""))) | C8: =IF(COUNTIFS(Risk_Register!$F$5:$F$17,3,Risk_Register!$G$5:$G$17,2)=0,"",COUNTIFS(Risk_Register!$F$5:$F$17,3,Risk_Register!$G$5:$G$17,2)&" · Medium"&CHAR(10)&TRIM(IF(Risk_Register!$V$5="3-2",Risk_Register!$A$5&" ","")&IF(Risk_Register!$V$6="3-2",Risk_Register!$A$6&" ","")&IF(Risk_Register!$V$7="3-2",Risk_Register!$A$7&" ","")&IF(Risk_Register!$V$8="3-2",Risk_Register!$A$8&" ","")&IF(Risk_Register!$V$9="3-2",Risk_Register!$A$9&" ","")&IF(Risk_Register!$V$10="3-2",Risk_Register!$A$10&" ","")&IF(Risk_Register!$V$11="3-2",Risk_Register!$A$11&" ","")&IF(Risk_Register!$V$12="3-2",Risk_Register!$A$12&" ","")&IF(Risk_Register!$V$13="3-2",Risk_Register!$A$13&" ","")&IF(Risk_Register!$V$14="3-2",Risk_Register!$A$14&" ","")&IF(Risk_Register!$V$15="3-2",Risk_Register!$A$15&" ","")&IF(Risk_Register!$V$16="3-2",Risk_Register!$A$16&" ","")&IF(Risk_Register!$V$17="3-2",Risk_Register!$A$17&" ",""))) | D8: =IF(COUNTIFS(Risk_Register!$F$5:$F$17,3,Risk_Register!$G$5:$G$17,3)=0,"",COUNTIFS(Risk_Register!$F$5:$F$17,3,Risk_Register!$G$5:$G$17,3)&" · Medium"&CHAR(10)&TRIM(IF(Risk_Register!$V$5="3-3",Risk_Register!$A$5&" ","")&IF(Risk_Register!$V$6="3-3",Risk_Register!$A$6&" ","")&IF(Risk_Register!$V$7="3-3",Risk_Register!$A$7&" ","")&IF(Risk_Register!$V$8="3-3",Risk_Register!$A$8&" ","")&IF(Risk_Register!$V$9="3-3",Risk_Register!$A$9&" ","")&IF(Risk_Register!$V$10="3-3",Risk_Register!$A$10&" ","")&IF(Risk_Register!$V$11="3-3",Risk_Register!$A$11&" ","")&IF(Risk_Register!$V$12="3-3",Risk_Register!$A$12&" ","")&IF(Risk_Register!$V$13="3-3",Risk_Register!$A$13&" ","")&IF(Risk_Register!$V$14="3-3",Risk_Register!$A$14&" ","")&IF(Risk_Register!$V$15="3-3",Risk_Register!$A$15&" ","")&IF(Risk_Register!$V$16="3-3",Risk_Register!$A$16&" ","")&IF(Risk_Register!$V$17="3-3",Risk_Register!$A$17&" ",""))) -> 4 · Medium R08 R09 R10 R12 | E8: =IF(COUNTIFS(Risk_Register!$F$5:$F$17,3,Risk_Register!$G$5:$G$17,4)=0,"",COUNTIFS(Risk_Register!$F$5:$F$17,3,Risk_Register!$G$5:$G$17,4)&" · High"&CHAR(10)&TRIM(IF(Risk_Register!$V$5="3-4",Risk_Register!$A$5&" ","")&IF(Risk_Register!$V$6="3-4",Risk_Register!$A$6&" ","")&IF(Risk_Register!$V$7="3-4",Risk_Register!$A$7&" ","")&IF(Risk_Register!$V$8="3-4",Risk_Register!$A$8&" ","")&IF(Risk_Register!$V$9="3-4",Risk_Register!$A$9&" ","")&IF(Risk_Register!$V$10="3-4",Risk_Register!$A$10&" ","")&IF(Risk_Register!$V$11="3-4",Risk_Register!$A$11&" ","")&IF(Risk_Register!$V$12="3-4",Risk_Register!$A$12&" ","")&IF(Risk_Register!$V$13="3-4",Risk_Register!$A$13&" ","")&IF(Risk_Register!$V$14="3-4",Risk_Register!$A$14&" ","")&IF(Risk_Register!$V$15="3-4",Risk_Register!$A$15&" ","")&IF(Risk_Register!$V$16="3-4",Risk_Register!$A$16&" ","")&IF(Risk_Register!$V$17="3-4",Risk_Register!$A$17&" ",""))) -> 2 · High R02 R04 | F8: =IF(COUNTIFS(Risk_Register!$F$5:$F$17,3,Risk_Register!$G$5:$G$17,5)=0,"",COUNTIFS(Risk_Register!$F$5:$F$17,3,Risk_Register!$G$5:$G$17,5)&" · High"&CHAR(10)&TRIM(IF(Risk_Register!$V$5="3-5",Risk_Register!$A$5&" ","")&IF(Risk_Register!$V$6="3-5",Risk_Register!$A$6&" ","")&IF(Risk_Register!$V$7="3-5",Risk_Register!$A$7&" ","")&IF(Risk_Register!$V$8="3-5",Risk_Register!$A$8&" ","")&IF(Risk_Register!$V$9="3-5",Risk_Register!$A$9&" ","")&IF(Risk_Register!$V$10="3-5",Risk_Register!$A$10&" ","")&IF(Risk_Register!$V$11="3-5",Risk_Register!$A$11&" ","")&IF(Risk_Register!$V$12="3-5",Risk_Register!$A$12&" ","")&IF(Risk_Register!$V$13="3-5",Risk_Register!$A$13&" ","")&IF(Risk_Register!$V$14="3-5",Risk_Register!$A$14&" ","")&IF(Risk_Register!$V$15="3-5",Risk_Register!$A$15&" ","")&IF(Risk_Register!$V$16="3-5",Risk_Register!$A$16&" ","")&IF(Risk_Register!$V$17="3-5",Risk_Register!$A$17&" ",""))) -> 1 · High R07 | G8: 3 Possible | H8: =IF(COUNTIFS(Risk_Register!$N$5:$N$17,3,Risk_Register!$O$5:$O$17,1)=0,"",COUNTIFS(Risk_Register!$N$5:$N$17,3,Risk_Register!$O$5:$O$17,1)&" · Low"&CHAR(10)&TRIM(IF(Risk_Register!$W$5="3-1",Risk_Register!$A$5&" ","")&IF(Risk_Register!$W$6="3-1",Risk_Register!$A$6&" ","")&IF(Risk_Register!$W$7="3-1",Risk_Register!$A$7&" ","")&IF(Risk_Register!$W$8="3-1",Risk_Register!$A$8&" ","")&IF(Risk_Register!$W$9="3-1",Risk_Register!$A$9&" ","")&IF(Risk_Register!$W$10="3-1",Risk_Register!$A$10&" ","")&IF(Risk_Register!$W$11="3-1",Risk_Register!$A$11&" ","")&IF(Risk_Register!$W$12="3-1",Risk_Register!$A$12&" ","")&IF(Risk_Register!$W$13="3-1",Risk_Register!$A$13&" ","")&IF(Risk_Register!$W$14="3-1",Risk_Register!$A$14&" ","")&IF(Risk_Register!$W$15="3-1",Risk_Register!$A$15&" ","")&IF(Risk_Register!$W$16="3-1",Risk_Register!$A$16&" ","")&IF(Risk_Register!$W$17="3-1",Risk_Register!$A$17&" ",""))) | I8: =IF(COUNTIFS(Risk_Register!$N$5:$N$17,3,Risk_Register!$O$5:$O$17,2)=0,"",COUNTIFS(Risk_Register!$N$5:$N$17,3,Risk_Register!$O$5:$O$17,2)&" · Medium"&CHAR(10)&TRIM(IF(Risk_Register!$W$5="3-2",Risk_Register!$A$5&" ","")&IF(Risk_Register!$W$6="3-2",Risk_Register!$A$6&" ","")&IF(Risk_Register!$W$7="3-2",Risk_Register!$A$7&" ","")&IF(Risk_Register!$W$8="3-2",Risk_Register!$A$8&" ","")&IF(Risk_Register!$W$9="3-2",Risk_Register!$A$9&" ","")&IF(Risk_Register!$W$10="3-2",Risk_Register!$A$10&" ","")&IF(Risk_Register!$W$11="3-2",Risk_Register!$A$11&" ","")&IF(Risk_Register!$W$12="3-2",Risk_Register!$A$12&" ","")&IF(Risk_Register!$W$13="3-2",Risk_Register!$A$13&" ","")&IF(Risk_Register!$W$14="3-2",Risk_Register!$A$14&" ","")&IF(Risk_Register!$W$15="3-2",Risk_Register!$A$15&" ","")&IF(Risk_Register!$W$16="3-2",Risk_Register!$A$16&" ","")&IF(Risk_Register!$W$17="3-2",Risk_Register!$A$17&" ",""))) | J8: =IF(COUNTIFS(Risk_Register!$N$5:$N$17,3,Risk_Register!$O$5:$O$17,3)=0,"",COUNTIFS(Risk_Register!$N$5:$N$17,3,Risk_Register!$O$5:$O$17,3)&" · Medium"&CHAR(10)&TRIM(IF(Risk_Register!$W$5="3-3",Risk_Register!$A$5&" ","")&IF(Risk_Register!$W$6="3-3",Risk_Register!$A$6&" ","")&IF(Risk_Register!$W$7="3-3",Risk_Register!$A$7&" ","")&IF(Risk_Register!$W$8="3-3",Risk_Register!$A$8&" ","")&IF(Risk_Register!$W$9="3-3",Risk_Register!$A$9&" ","")&IF(Risk_Register!$W$10="3-3",Risk_Register!$A$10&" ","")&IF(Risk_Register!$W$11="3-3",Risk_Register!$A$11&" ","")&IF(Risk_Register!$W$12="3-3",Risk_Register!$A$12&" ","")&IF(Risk_Register!$W$13="3-3",Risk_Register!$A$13&" ","")&IF(Risk_Register!$W$14="3-3",Risk_Register!$A$14&" ","")&IF(Risk_Register!$W$15="3-3",Risk_Register!$A$15&" ","")&IF(Risk_Register!$W$16="3-3",Risk_Register!$A$16&" ","")&IF(Risk_Register!$W$17="3-3",Risk_Register!$A$17&" ",""))) | K8: =IF(COUNTIFS(Risk_Register!$N$5:$N$17,3,Risk_Register!$O$5:$O$17,4)=0,"",COUNTIFS(Risk_Register!$N$5:$N$17,3,Risk_Register!$O$5:$O$17,4)&" · High"&CHAR(10)&TRIM(IF(Risk_Register!$W$5="3-4",Risk_Register!$A$5&" ","")&IF(Risk_Register!$W$6="3-4",Risk_Register!$A$6&" ","")&IF(Risk_Register!$W$7="3-4",Risk_Register!$A$7&" ","")&IF(Risk_Register!$W$8="3-4",Risk_Register!$A$8&" ","")&IF(Risk_Register!$W$9="3-4",Risk_Register!$A$9&" ","")&IF(Risk_Register!$W$10="3-4",Risk_Register!$A$10&" ","")&IF(Risk_Register!$W$11="3-4",Risk_Register!$A$11&" ","")&IF(Risk_Register!$W$12="3-4",Risk_Register!$A$12&" ","")&IF(Risk_Register!$W$13="3-4",Risk_Register!$A$13&" ","")&IF(Risk_Register!$W$14="3-4",Risk_Register!$A$14&" ","")&IF(Risk_Register!$W$15="3-4",Risk_Register!$A$15&" ","")&IF(Risk_Register!$W$16="3-4",Risk_Register!$A$16&" ","")&IF(Risk_Register!$W$17="3-4",Risk_Register!$A$17&" ",""))) | L8: =IF(COUNTIFS(Risk_Register!$N$5:$N$17,3,Risk_Register!$O$5:$O$17,5)=0,"",COUNTIFS(Risk_Register!$N$5:$N$17,3,Risk_Register!$O$5:$O$17,5)&" · High"&CHAR(10)&TRIM(IF(Risk_Register!$W$5="3-5",Risk_Register!$A$5&" ","")&IF(Risk_Register!$W$6="3-5",Risk_Register!$A$6&" ","")&IF(Risk_Register!$W$7="3-5",Risk_Register!$A$7&" ","")&IF(Risk_Register!$W$8="3-5",Risk_Register!$A$8&" ","")&IF(Risk_Register!$W$9="3-5",Risk_Register!$A$9&" ","")&IF(Risk_Register!$W$10="3-5",Risk_Register!$A$10&" ","")&IF(Risk_Register!$W$11="3-5",Risk_Register!$A$11&" ","")&IF(Risk_Register!$W$12="3-5",Risk_Register!$A$12&" ","")&IF(Risk_Register!$W$13="3-5",Risk_Register!$A$13&" ","")&IF(Risk_Register!$W$14="3-5",Risk_Register!$A$14&" ","")&IF(Risk_Register!$W$15="3-5",Risk_Register!$A$15&" ","")&IF(Risk_Register!$W$16="3-5",Risk_Register!$A$16&" ","")&IF(Risk_Register!$W$17="3-5",Risk_Register!$A$17&" ","")))
A9: 2 Unlikely | B9: =IF(COUNTIFS(Risk_Register!$F$5:$F$17,2,Risk_Register!$G$5:$G$17,1)=0,"",COUNTIFS(Risk_Register!$F$5:$F$17,2,Risk_Register!$G$5:$G$17,1)&" · Low"&CHAR(10)&TRIM(IF(Risk_Register!$V$5="2-1",Risk_Register!$A$5&" ","")&IF(Risk_Register!$V$6="2-1",Risk_Register!$A$6&" ","")&IF(Risk_Register!$V$7="2-1",Risk_Register!$A$7&" ","")&IF(Risk_Register!$V$8="2-1",Risk_Register!$A$8&" ","")&IF(Risk_Register!$V$9="2-1",Risk_Register!$A$9&" ","")&IF(Risk_Register!$V$10="2-1",Risk_Register!$A$10&" ","")&IF(Risk_Register!$V$11="2-1",Risk_Register!$A$11&" ","")&IF(Risk_Register!$V$12="2-1",Risk_Register!$A$12&" ","")&IF(Risk_Register!$V$13="2-1",Risk_Register!$A$13&" ","")&IF(Risk_Register!$V$14="2-1",Risk_Register!$A$14&" ","")&IF(Risk_Register!$V$15="2-1",Risk_Register!$A$15&" ","")&IF(Risk_Register!$V$16="2-1",Risk_Register!$A$16&" ","")&IF(Risk_Register!$V$17="2-1",Risk_Register!$A$17&" ",""))) | C9: =IF(COUNTIFS(Risk_Register!$F$5:$F$17,2,Risk_Register!$G$5:$G$17,2)=0,"",COUNTIFS(Risk_Register!$F$5:$F$17,2,Risk_Register!$G$5:$G$17,2)&" · Low"&CHAR(10)&TRIM(IF(Risk_Register!$V$5="2-2",Risk_Register!$A$5&" ","")&IF(Risk_Register!$V$6="2-2",Risk_Register!$A$6&" ","")&IF(Risk_Register!$V$7="2-2",Risk_Register!$A$7&" ","")&IF(Risk_Register!$V$8="2-2",Risk_Register!$A$8&" ","")&IF(Risk_Register!$V$9="2-2",Risk_Register!$A$9&" ","")&IF(Risk_Register!$V$10="2-2",Risk_Register!$A$10&" ","")&IF(Risk_Register!$V$11="2-2",Risk_Register!$A$11&" ","")&IF(Risk_Register!$V$12="2-2",Risk_Register!$A$12&" ","")&IF(Risk_Register!$V$13="2-2",Risk_Register!$A$13&" ","")&IF(Risk_Register!$V$14="2-2",Risk_Register!$A$14&" ","")&IF(Risk_Register!$V$15="2-2",Risk_Register!$A$15&" ","")&IF(Risk_Register!$V$16="2-2",Risk_Register!$A$16&" ","")&IF(Risk_Register!$V$17="2-2",Risk_Register!$A$17&" ",""))) | D9: =IF(COUNTIFS(Risk_Register!$F$5:$F$17,2,Risk_Register!$G$5:$G$17,3)=0,"",COUNTIFS(Risk_Register!$F$5:$F$17,2,Risk_Register!$G$5:$G$17,3)&" · Medium"&CHAR(10)&TRIM(IF(Risk_Register!$V$5="2-3",Risk_Register!$A$5&" ","")&IF(Risk_Register!$V$6="2-3",Risk_Register!$A$6&" ","")&IF(Risk_Register!$V$7="2-3",Risk_Register!$A$7&" ","")&IF(Risk_Register!$V$8="2-3",Risk_Register!$A$8&" ","")&IF(Risk_Register!$V$9="2-3",Risk_Register!$A$9&" ","")&IF(Risk_Register!$V$10="2-3",Risk_Register!$A$10&" ","")&IF(Risk_Register!$V$11="2-3",Risk_Register!$A$11&" ","")&IF(Risk_Register!$V$12="2-3",Risk_Register!$A$12&" ","")&IF(Risk_Register!$V$13="2-3",Risk_Register!$A$13&" ","")&IF(Risk_Register!$V$14="2-3",Risk_Register!$A$14&" ","")&IF(Risk_Register!$V$15="2-3",Risk_Register!$A$15&" ","")&IF(Risk_Register!$V$16="2-3",Risk_Register!$A$16&" ","")&IF(Risk_Register!$V$17="2-3",Risk_Register!$A$17&" ",""))) -> 1 · Medium R05 | E9: =IF(COUNTIFS(Risk_Register!$F$5:$F$17,2,Risk_Register!$G$5:$G$17,4)=0,"",COUNTIFS(Risk_Register!$F$5:$F$17,2,Risk_Register!$G$5:$G$17,4)&" · Medium"&CHAR(10)&TRIM(IF(Risk_Register!$V$5="2-4",Risk_Register!$A$5&" ","")&IF(Risk_Register!$V$6="2-4",Risk_Register!$A$6&" ","")&IF(Risk_Register!$V$7="2-4",Risk_Register!$A$7&" ","")&IF(Risk_Register!$V$8="2-4",Risk_Register!$A$8&" ","")&IF(Risk_Register!$V$9="2-4",Risk_Register!$A$9&" ","")&IF(Risk_Register!$V$10="2-4",Risk_Register!$A$10&" ","")&IF(Risk_Register!$V$11="2-4",Risk_Register!$A$11&" ","")&IF(Risk_Register!$V$12="2-4",Risk_Register!$A$12&" ","")&IF(Risk_Register!$V$13="2-4",Risk_Register!$A$13&" ","")&IF(Risk_Register!$V$14="2-4",Risk_Register!$A$14&" ","")&IF(Risk_Register!$V$15="2-4",Risk_Register!$A$15&" ","")&IF(Risk_Register!$V$16="2-4",Risk_Register!$A$16&" ","")&IF(Risk_Register!$V$17="2-4",Risk_Register!$A$17&" ",""))) | F9: =IF(COUNTIFS(Risk_Register!$F$5:$F$17,2,Risk_Register!$G$5:$G$17,5)=0,"",COUNTIFS(Risk_Register!$F$5:$F$17,2,Risk_Register!$G$5:$G$17,5)&" · High"&CHAR(10)&TRIM(IF(Risk_Register!$V$5="2-5",Risk_Register!$A$5&" ","")&IF(Risk_Register!$V$6="2-5",Risk_Register!$A$6&" ","")&IF(Risk_Register!$V$7="2-5",Risk_Register!$A$7&" ","")&IF(Risk_Register!$V$8="2-5",Risk_Register!$A$8&" ","")&IF(Risk_Register!$V$9="2-5",Risk_Register!$A$9&" ","")&IF(Risk_Register!$V$10="2-5",Risk_Register!$A$10&" ","")&IF(Risk_Register!$V$11="2-5",Risk_Register!$A$11&" ","")&IF(Risk_Register!$V$12="2-5",Risk_Register!$A$12&" ","")&IF(Risk_Register!$V$13="2-5",Risk_Register!$A$13&" ","")&IF(Risk_Register!$V$14="2-5",Risk_Register!$A$14&" ","")&IF(Risk_Register!$V$15="2-5",Risk_Register!$A$15&" ","")&IF(Risk_Register!$V$16="2-5",Risk_Register!$A$16&" ","")&IF(Risk_Register!$V$17="2-5",Risk_Register!$A$17&" ",""))) -> 1 · High R03 | G9: 2 Unlikely | H9: =IF(COUNTIFS(Risk_Register!$N$5:$N$17,2,Risk_Register!$O$5:$O$17,1)=0,"",COUNTIFS(Risk_Register!$N$5:$N$17,2,Risk_Register!$O$5:$O$17,1)&" · Low"&CHAR(10)&TRIM(IF(Risk_Register!$W$5="2-1",Risk_Register!$A$5&" ","")&IF(Risk_Register!$W$6="2-1",Risk_Register!$A$6&" ","")&IF(Risk_Register!$W$7="2-1",Risk_Register!$A$7&" ","")&IF(Risk_Register!$W$8="2-1",Risk_Register!$A$8&" ","")&IF(Risk_Register!$W$9="2-1",Risk_Register!$A$9&" ","")&IF(Risk_Register!$W$10="2-1",Risk_Register!$A$10&" ","")&IF(Risk_Register!$W$11="2-1",Risk_Register!$A$11&" ","")&IF(Risk_Register!$W$12="2-1",Risk_Register!$A$12&" ","")&IF(Risk_Register!$W$13="2-1",Risk_Register!$A$13&" ","")&IF(Risk_Register!$W$14="2-1",Risk_Register!$A$14&" ","")&IF(Risk_Register!$W$15="2-1",Risk_Register!$A$15&" ","")&IF(Risk_Register!$W$16="2-1",Risk_Register!$A$16&" ","")&IF(Risk_Register!$W$17="2-1",Risk_Register!$A$17&" ",""))) | I9: =IF(COUNTIFS(Risk_Register!$N$5:$N$17,2,Risk_Register!$O$5:$O$17,2)=0,"",COUNTIFS(Risk_Register!$N$5:$N$17,2,Risk_Register!$O$5:$O$17,2)&" · Low"&CHAR(10)&TRIM(IF(Risk_Register!$W$5="2-2",Risk_Register!$A$5&" ","")&IF(Risk_Register!$W$6="2-2",Risk_Register!$A$6&" ","")&IF(Risk_Register!$W$7="2-2",Risk_Register!$A$7&" ","")&IF(Risk_Register!$W$8="2-2",Risk_Register!$A$8&" ","")&IF(Risk_Register!$W$9="2-2",Risk_Register!$A$9&" ","")&IF(Risk_Register!$W$10="2-2",Risk_Register!$A$10&" ","")&IF(Risk_Register!$W$11="2-2",Risk_Register!$A$11&" ","")&IF(Risk_Register!$W$12="2-2",Risk_Register!$A$12&" ","")&IF(Risk_Register!$W$13="2-2",Risk_Register!$A$13&" ","")&IF(Risk_Register!$W$14="2-2",Risk_Register!$A$14&" ","")&IF(Risk_Register!$W$15="2-2",Risk_Register!$A$15&" ","")&IF(Risk_Register!$W$16="2-2",Risk_Register!$A$16&" ","")&IF(Risk_Register!$W$17="2-2",Risk_Register!$A$17&" ",""))) -> 2 · Low R05 R09 | J9: =IF(COUNTIFS(Risk_Register!$N$5:$N$17,2,Risk_Register!$O$5:$O$17,3)=0,"",COUNTIFS(Risk_Register!$N$5:$N$17,2,Risk_Register!$O$5:$O$17,3)&" · Medium"&CHAR(10)&TRIM(IF(Risk_Register!$W$5="2-3",Risk_Register!$A$5&" ","")&IF(Risk_Register!$W$6="2-3",Risk_Register!$A$6&" ","")&IF(Risk_Register!$W$7="2-3",Risk_Register!$A$7&" ","")&IF(Risk_Register!$W$8="2-3",Risk_Register!$A$8&" ","")&IF(Risk_Register!$W$9="2-3",Risk_Register!$A$9&" ","")&IF(Risk_Register!$W$10="2-3",Risk_Register!$A$10&" ","")&IF(Risk_Register!$W$11="2-3",Risk_Register!$A$11&" ","")&IF(Risk_Register!$W$12="2-3",Risk_Register!$A$12&" ","")&IF(Risk_Register!$W$13="2-3",Risk_Register!$A$13&" ","")&IF(Risk_Register!$W$14="2-3",Risk_Register!$A$14&" ","")&IF(Risk_Register!$W$15="2-3",Risk_Register!$A$15&" ","")&IF(Risk_Register!$W$16="2-3",Risk_Register!$A$16&" ","")&IF(Risk_Register!$W$17="2-3",Risk_Register!$A$17&" ",""))) -> 4 · Medium R01 R02 R06 R11 | K9: =IF(COUNTIFS(Risk_Register!$N$5:$N$17,2,Risk_Register!$O$5:$O$17,4)=0,"",COUNTIFS(Risk_Register!$N$5:$N$17,2,Risk_Register!$O$5:$O$17,4)&" · Medium"&CHAR(10)&TRIM(IF(Risk_Register!$W$5="2-4",Risk_Register!$A$5&" ","")&IF(Risk_Register!$W$6="2-4",Risk_Register!$A$6&" ","")&IF(Risk_Register!$W$7="2-4",Risk_Register!$A$7&" ","")&IF(Risk_Register!$W$8="2-4",Risk_Register!$A$8&" ","")&IF(Risk_Register!$W$9="2-4",Risk_Register!$A$9&" ","")&IF(Risk_Register!$W$10="2-4",Risk_Register!$A$10&" ","")&IF(Risk_Register!$W$11="2-4",Risk_Register!$A$11&" ","")&IF(Risk_Register!$W$12="2-4",Risk_Register!$A$12&" ","")&IF(Risk_Register!$W$13="2-4",Risk_Register!$A$13&" ","")&IF(Risk_Register!$W$14="2-4",Risk_Register!$A$14&" ","")&IF(Risk_Register!$W$15="2-4",Risk_Register!$A$15&" ","")&IF(Risk_Register!$W$16="2-4",Risk_Register!$A$16&" ","")&IF(Risk_Register!$W$17="2-4",Risk_Register!$A$17&" ",""))) -> 1 · Medium R07 | L9: =IF(COUNTIFS(Risk_Register!$N$5:$N$17,2,Risk_Register!$O$5:$O$17,5)=0,"",COUNTIFS(Risk_Register!$N$5:$N$17,2,Risk_Register!$O$5:$O$17,5)&" · High"&CHAR(10)&TRIM(IF(Risk_Register!$W$5="2-5",Risk_Register!$A$5&" ","")&IF(Risk_Register!$W$6="2-5",Risk_Register!$A$6&" ","")&IF(Risk_Register!$W$7="2-5",Risk_Register!$A$7&" ","")&IF(Risk_Register!$W$8="2-5",Risk_Register!$A$8&" ","")&IF(Risk_Register!$W$9="2-5",Risk_Register!$A$9&" ","")&IF(Risk_Register!$W$10="2-5",Risk_Register!$A$10&" ","")&IF(Risk_Register!$W$11="2-5",Risk_Register!$A$11&" ","")&IF(Risk_Register!$W$12="2-5",Risk_Register!$A$12&" ","")&IF(Risk_Register!$W$13="2-5",Risk_Register!$A$13&" ","")&IF(Risk_Register!$W$14="2-5",Risk_Register!$A$14&" ","")&IF(Risk_Register!$W$15="2-5",Risk_Register!$A$15&" ","")&IF(Risk_Register!$W$16="2-5",Risk_Register!$A$16&" ","")&IF(Risk_Register!$W$17="2-5",Risk_Register!$A$17&" ","")))
